Workbook

Sheet Leia-me
A1: Banco de dados do Encaminha Goiânia
A3: Para que serve | B3: Guarda os dados do app fora dele: serviços e contatos da rede, textos das políticas, temas do pedido livre e os atendimentos registrados de forma anônima. A equipe gestora atualiza aqui; o app lê daqui.
A4: Serviços | B4: Um serviço por linha. Atualize telefone, endereço, horário e observação. Ao conferir, mude a Situação e preencha Conferido em e Conferido por. A coluna Precisa conferir? avisa sozinha: Sim quando nunca foi conferido ou passou de 180 dias.
A5: Políticas | B5: Nome, valor, passo a passo e documentos de cada política. Uma linha do passo a passo por linha da célula. Quem tem direito (o critério) fica no código do app e é testado; para mudar um critério, escreva o pedido na coluna Mudança de critério pedida.
A6: Temas | B6: Situações que o app reconhece no pedido livre. Palavras-chave sem acento, separadas por vírgula. Uma palavra curta (até 3 letras) precisa aparecer inteira; as demais valem no começo de uma palavra.
A7: Registros | B7: Preenchida pelo app quando o profissional toca em Registrar atendimento. Não edite à mão. Só dados anônimos: nada de nome, iniciais, texto livre, renda ou idade exatas.
A8: Resumo | B8: Contagens por fórmula sobre a aba Registros. Atualiza sozinha quando chegam registros.
A9: Fontes | B9: De onde veio cada tabela e quando foi exportada.
A10: Como editar | B10: Não mude a coluna ID nem a ordem das colunas: o app usa os IDs para ligar políticas, temas e serviços. Para incluir um serviço novo, use uma linha nova no fim, com um ID novo, curto e sem espaço (ex.: caps-ad-leste).
A11: Legenda | B11: Células em amarelo claro: colunas de conferência que a equipe preenche.
A12: LGPD | B12: Nunca registre nome, CPF, NIS, endereço, telefone ou e-mail de pessoa atendida. Raça, religião, orientação sexual e dados de saúde de uma pessoa identificável são dados sensíveis. Os registros do app são anônimos e situações sensíveis com 1 ou 2 casos não devem ser divulgadas.
A13: Acesso | B13: Edição só para a equipe gestora. Para profissionais que só consultam, compartilhe como Leitor.

Sheet Serviços
A1: ID (não altere) | B1: Nome | C1: Tipo | D1: Município | E1: Região de Goiânia | F1: Endereço | G1: Telefones (separe com /) | H1: E-mail | I1: Horário | J1: Site | K1: Observação | L1: Fonte | M1: Situação | N1: Conferido em | O1: Conferido por (setor) | P1: Precisa conferir?
A2: mxc | B2: Unidade de Integração e Referência Social Maria Xavier Caiado | C2: Estadual (Seds) | D2: Estado | F2: Av. Anhanguera, 3463, Setor Leste Universitário, Goiânia, CEP 74610-010 | G2: (62) 3270-9610 | I2: Seg a sex, 8h às 17h | K2: Entrega e 2ª via dos cartões Mães de Goiás, Dignidade e Goiás + Inclusivo. CIPTEA, Passe Livre PcD e Passaporte da Pessoa Idosa. | L2: Protótipo do app (ver aba Fontes) | M2: Ativo | P2: =IF($A2="","",IF($M2="Inativo","Não",IF($N2="","Sim",IF(TODAY()-$N2>180,"Sim","Não"))))
A3: seds | B3: Seds, Secretaria de Estado de Desenvolvimento Social | C3: Estadual (Seds) | D3: Estado | F3: Praça Dr. Pedro Ludovico Teixeira, 332, Blocos A a D, Setor Central, Goiânia, CEP 74003-010 | G3: (62) 3270-9603 / Ouvidoria (62) 3270-9604 | H3: ouvidoria.seds@goias.gov.br | I3: Seg a sex, 8h às 18h | L3: Protótipo do app (ver aba Fontes) | M3: Ativo | P3: =IF($A3="","",IF($M3="Inativo","Não",IF($N3="","Sim",IF(TODAY()-$N3>180,"Sim","Não"))))
A4: pcd | B4: Gerência da Pessoa com Deficiência (Seds) | C4: Estadual (Seds) | D4: Estado | F4: Av. Anhanguera, 3463, Setor Leste Universitário, Goiânia, CEP 74610-010 | G4: (62) 3270-9620 / WhatsApp (62) 98104-3652 | H4: pcd@goias.gov.br | I4: Seg a sex, 7h30 às 18h | L4: Protótipo do app (ver aba Fontes) | M4: Ativo | P4: =IF($A4="","",IF($M4="Inativo","Não",IF($N4="","Sim",IF(TODAY()-$N4>180,"Sim","Não"))))
A5: passaporte | B5: Passaporte da Pessoa Idosa (Seds) | C5: Estadual (Seds) | D5: Estado | F5: Av. Anhanguera, 3463, Setor Leste Universitário, Goiânia, CEP 74610-010 | G5: (62) 3270-9621 / (62) 98306-0327 | H5: passaporte.seds@goias.gov.br | I5: Seg a sex, 7h às 17h30 | L5: Protótipo do app (ver aba Fontes) | M5: Ativo | P5: =IF($A5="","",IF($M5="Inativo","Não",IF($N5="","Sim",IF(TODAY()-$N5>180,"Sim","Não"))))
A6: mulherseds | B6: Superintendência da Mulher (Seds), Goiás Por Elas | C6: Estadual (Seds) | D6: Estado | F6: Praça Dr. Pedro Ludovico Teixeira, 332, Bloco B, térreo, Setor Central, Goiânia | G6: WhatsApp (62) 98270-0214 | H6: crei.seds@goias.gov.br | L6: Protótipo do app (ver aba Fontes) | M6: Ativo | P6: =IF($A6="","",IF($M6="Inativo","Não",IF($N6="","Sim",IF(TODAY()-$N6>180,"Sim","Não"))))
A7: juventude | B7: Passe Livre Estudantil (Seds) | C7: Estadual (Seds) | D7: Estado | F7: Praça Dr. Pedro Ludovico Teixeira, 332, Bloco C, térreo, Setor Central, Goiânia, CEP 74083-010 | G7: (62) 3270-9624 / WhatsApp (62) 98306-0294 / RedeMob 0800 648 2222 | H7: passelivre@goias.gov.br | J7: https://www.juventude.go.gov.br/ | L7: Protótipo do app (ver aba Fontes) | M7: Ativo | P7: =IF($A7="","",IF($M7="Inativo","Não",IF($N7="","Sim",IF(TODAY()-$N7>180,"Sim","Não"))))
A8: registro | B8: Registro Civil, 2ª via gratuita (Seds) | C8: Estadual (Seds) | D8: Estado | F8: Av. Anhanguera, 3463, Setor Leste Universitário, Goiânia, CEP 74610-010 | G8: WhatsApp (62) 3270-9644 | H8: garantiadedireitos.seds@goias.gov.br | L8: Protótipo do app (ver aba Fontes) | M8: Ativo | P8: =IF($A8="","",IF($M8="Inativo","Não",IF($N8="","Sim",IF(TODAY()-$N8>180,"Sim","Não"))))
A9: agehab | B9: Agehab, Agência Goiana de Habitação | C9: Estadual (Agehab) | D9: Estado | F9: Rua 18-A, nº 541, Setor Aeroporto, Goiânia, CEP 74070-060 | G9: (62) 3096-5005 / (62) 3096-5050 | I9: 8h às 17h | J9: https://aluguelsocial.agehab.go.gov.br | L9: Protótipo do app (ver aba Fontes) | M9: Ativo | P9: =IF($A9="","",IF($M9="Inativo","Não",IF($N9="","Sim",IF(TODAY()-$N9>180,"Sim","Não"))))
A10: aprendiz | B10: Aprendiz do Futuro | C10: Estadual (Seds) | D10: Estado | G10: 0800 494 1052 | J10: https://aprendizdofuturo.org.br | L10: Protótipo do app (ver aba Fontes) | M10: Ativo | P10: =IF($A10="","",IF($M10="Inativo","Não",IF($N10="","Sim",IF(TODAY()-$N10>180,"Sim","Não"))))
A11: 121 | B11: Disque Social 121 (MDS) | C11: Nacional | D11: Nacional | G11: 121 | K11: Bolsa Família, Cadastro Único e endereço do CRAS mais próximo. | L11: Protótipo do app (ver aba Fontes) | M11: Ativo | P11: =IF($A11="","",IF($M11="Inativo","Não",IF($N11="","Sim",IF(TODAY()-$N11>180,"Sim","Não"))))
A12: 135 | B12: INSS, Central 135 e Meu INSS | C12: Nacional | D12: Nacional | G12: 135 | J12: https://meu.inss.gov.br | K12: Pedido de BPC, agendamento de perícia e avaliação social. | L12: Protótipo do app (ver aba Fontes) | M12: Ativo | P12: =IF($A12="","",IF($M12="Inativo","Não",IF($N12="","Sim",IF(TODAY()-$N12>180,"Sim","Não"))))
A13: 100 | B13: Disque 100, Direitos Humanos | C13: Nacional | D13: Nacional | G13: 100 | K13: Denúncia anônima de violência contra criança, idoso, pessoa com deficiência, população de rua e LGBTQIA+, tráfico de pessoas e trabalho escravo. 24h. Também por WhatsApp (61) 99611-0100. | L13: Protótipo do app (ver aba Fontes) | M13: Ativo | P13: =IF($A13="","",IF($M13="Inativo","Não",IF($N13="","Sim",IF(TODAY()-$N13>180,"Sim","Não"))))
A14: 180 | B14: Ligue 180, Central de Atendimento à Mulher | C14: Nacional | D14: Nacional | G14: 180 | K14: Gratuito, sigiloso, 24h. | L14: Protótipo do app (ver aba Fontes) | M14: Ativo | P14: =IF($A14="","",IF($M14="Inativo","Não",IF($N14="","Sim",IF(TODAY()-$N14>180,"Sim","Não"))))
A15: 188 | B15: CVV, Centro de Valorização da Vida | C15: Nacional | D15: Nacional | G15: 188 | I15: Telefone 24h, todos os dias | J15: https://cvv.org.br | K15: Apoio emocional e prevenção do suicídio. Ligação gratuita e sigilosa, de qualquer telefone. Também há chat em cvv.org.br, em horários limitados: confira no site. | L15: Protótipo do app (ver aba Fontes) | M15: Ativo | P15: =IF($A15="","",IF($M15="Inativo","Não",IF($N15="","Sim",IF(TODAY()-$N15>180,"Sim","Não"))))
A16: ciatox | B16: CIATox Goiás, Centro de Informação e Assistência Toxicológica | C16: Saúde | D16: Estado | G16: 0800 646 4350 | I16: 24h, todos os dias | J16: https://goias.gov.br/saude/ciatox/ | K16: Orienta profissionais e população em intoxicação por remédio, veneno, agrotóxico, produto de limpeza ou animal peçonhento. Fonte: SES/GO, consultado em 08/10/2026. | L16: SES/GO, consultado em 08/10/2026 | M16: Ativo | N16: 46303 | O16: Levantamento de 08/10/2026 | P16: =IF($A16="","",IF($M16="Inativo","Não",IF($N16="","Sim",IF(TODAY()-$N16>180,"Sim","Não"))))
A17: crer | B17: CRER, Centro Estadual de Reabilitação e Readaptação Dr. Henrique Santillo | C17: Saúde | D17: Estado | F17: Av. Vereador José Monteiro, 1655, Setor Negrão de Lima, Goiânia, CEP 74653-230 | G17: Recepção (62) 3232-3232 / (62) 3232-3000 | J17: https://goias.gov.br/saude/crer/ | K17: Reabilitação pelo SUS. A primeira consulta é agendada pela regulação, com encaminhamento da UBS; não há procura direta. Fonte: SES/GO, consultado em 08/10/2026. | L17: SES/GO, consultado em 08/10/2026 | M17: Ativo | N17: 46303 | O17: Levantamento de 08/10/2026 | P17: =IF($A17="","",IF($M17="Inativo","Não",IF($N17="","Sim",IF(TODAY()-$N17>180,"Sim","Não"))))
A18: credeq | B18: Credeq Prof. Jamil Issy, referência estadual em dependência química | C18: Saúde | D18: Aparecida de Goiânia | K18: Casos graves de álcool e drogas, com internação voluntária de até 90 dias. A vaga vem pela regulação, com encaminhamento do CAPS AD. Fonte: Governo de Goiás e imprensa; endereço e telefone ainda não conferidos. | L18: Governo de Goiás e imprensa; endereço e telefone ainda não conferidos | M18: A conferir | P18: =IF($A18="","",IF($M18="Inativo","Não",IF($N18="","Sim",IF(TODAY()-$N18>180,"Sim","Não"))))
A19: autoexclusao | B19: Autoexclusão de apostas (Ministério da Fazenda) | C19: Nacional | D19: Nacional | J19: https://www.gov.br/pt-br/servicos/plataforma-centralizada-de-autoexclusao-apostas | K19: Bloqueia o CPF em todas as bets autorizadas, de 1 a 12 meses ou por tempo indeterminado, e corta a publicidade. Exige conta gov.br prata ou ouro. Fonte: gov.br, consultado em 08/10/2026. | L19: gov.br, consultado em 08/10/2026 | M19: Ativo | N19: 46303 | O19: Levantamento de 08/10/2026 | P19: =IF($A19="","",IF($M19="Inativo","Não",IF($N19="","Sim",IF(TODAY()-$N19>180,"Sim","Não"))))
A20: sine | B20: Sine Goiânia | C20: Trabalho | D20: Goiânia | F20: Rua 1, nº 147, Setor Central, Goiânia | K20: Vagas, seguro-desemprego e orientação profissional. Agendamento pelo app Prefeitura 24h. Levar RG, CPF, carteira de trabalho e comprovante de endereço. Endereço de reportagem recente: confirme antes de ir. | L20: Protótipo do app (ver aba Fontes) | M20: A conferir | P20: =IF($A20="","",IF($M20="Inativo","Não",IF($N20="","Sim",IF(TODAY()-$N20>180,"Sim","Não"))))
A21: procon | B21: Procon Goiás | C21: Justiça e direitos | D21: Estado | F21: Rua 8, nº 242, Setor Central, Goiânia | G21: Goiânia 151 / Interior (62) 3201-7124 / Superendividados (62) 3201-2891 | I21: Seg a sex, 8h às 17h | J21: https://www.procon.go.gov.br | K21: Reclamação de consumo, juros abusivos e renegociação de dívidas (Núcleo de Apoio aos Superendividados). Fonte: Procon Goiás, 2022: confirme os telefones. | L21: Procon Goiás, 2022: confirme os telefones | M21: A conferir | P21: =IF($A21="","",IF($M21="Inativo","Não",IF($N21="","Sim",IF(TODAY()-$N21>180,"Sim","Não"))))
A22: pc197 | B22: Disque Polícia Civil 197 | C22: Justiça e direitos | D22: Estado | G22: 197 | I22: 24h | K22: Orientação e denúncia à Polícia Civil de Goiás. | L22: Protótipo do app (ver aba Fontes) | M22: Ativo | P22: =IF($A22="","",IF($M22="Inativo","Não",IF($N22="","Sim",IF(TODAY()-$N22>180,"Sim","Não"))))
A23: dpca | B23: DPCA, Delegacia de Proteção à Criança e ao Adolescente | C23: Justiça e direitos | D23: Goiânia | F23: Rua C-190 esq. c/ C-107, Qd. 226, Lt. 13, Jardim América, Goiânia, CEP 74255-080 | G23: (62) 3286-1540 / (62) 3286-1298 / (62) 3286-1552 | H23: dpca.goiania.pcgo@pc.goias.gov.br | I23: Seg a sex, 8h às 12h e 14h às 18h | K23: Crimes contra crianças e adolescentes, inclusive violência sexual. Fonte: Polícia Civil de Goiás, consultado em 08/10/2026. | L23: Polícia Civil de Goiás, consultado em 08/10/2026 | M23: Ativo | N23: 46303 | O23: Levantamento de 08/10/2026 | P23: =IF($A23="","",IF($M23="Inativo","Não",IF($N23="","Sim",IF(TODAY()-$N23>180,"Sim","Não"))))
A24: deacri | B24: Deacri, Delegacia de Crimes Raciais e de Intolerância | C24: Justiça e direitos | D24: Goiânia | F24: Av. 2ª Radial, Qd. 48, Lt. 28, Setor Pedro Ludovico, Goiânia, CEP 74820-090 | G24: (62) 98495-2047 | H24: deacri.pcgo@pc.goias.gov.br | I24: Seg a sex, 8h às 18h | K24: Racismo, injúria racial, xenofobia, intolerância religiosa e LGBTfobia, inclusive ataques a terreiros. Também é possível registrar em qualquer delegacia ou pelo 197. Fonte: Polícia Civil de Goiás, consultado em 08/10/2026. | L24: Polícia Civil de Goiás, consultado em 08/10/2026 | M24: Ativo | N24: 46303 | O24: Levantamento de 08/10/2026 | P24: =IF($A24="","",IF($M24="Inativo","Não",IF($N24="","Sim",IF(TODAY()-$N24>180,"Sim","Não"))))
A25: crei | B25: Crei, Centro de Referência Estadual da Igualdade (Seds) | C25: Justiça e direitos | D25: Estado | H25: crei.seds@goias.gov.br | J25: https://goias.gov.br/social/superintendencia-da-igualdade-racial/ | K25: Atendimento psicológico, social e jurídico gratuito, presencial e on-line, a vítimas de racismo, intolerância religiosa e outras discriminações. Ligado à Superintendência da Igualdade Racial, que tem gerência para povos de terreiro. Fonte: Seds/GO; o e-mail aparece também na Superintendência da Mulher: confirme. | L25: Seds/GO; o e-mail aparece também na Superintendência da Mulher: confirme | M25: A conferir | P25: =IF($A25="","",IF($M25="Inativo","Não",IF($N25="","Sim",IF(TODAY()-$N25>180,"Sim","Não"))))
A26: deai | B26: Delegacia Estadual de Atendimento ao Idoso | C26: Justiça e direitos | D26: Goiânia | F26: Av. Anhanguera, nº 463, Setor Universitário, Goiânia | G26: (62) 3201-1501 / (62) 3201-1511 | I26: 8h às 18h | K26: Crimes contra a pessoa idosa. Dados da inauguração (2016): confirme antes de ir ou use o 197. | L26: Protótipo do app (ver aba Fontes) | M26: A conferir | P26: =IF($A26="","",IF($M26="Inativo","Não",IF($N26="","Sim",IF(TODAY()-$N26>180,"Sim","Não"))))
A27: hc-ufg | B27: Hospital das Clínicas da UFG (Ebserh) | C27: Saúde | D27: Goiânia | G27: (62) 3269-8380 | J27: https://www.gov.br/ebserh/pt-br/hospitais-universitarios/regiao-centro-oeste/hc-ufg | K27: Hospital-escola 100% SUS. Consultas e cirurgias pela regulação, com encaminhamento da UBS. Telefone de 2021: confirme. Carta de Serviços 2026 no site. | L27: Protótipo do app (ver aba Fontes) | M27: A conferir | P27: =IF($A27="","",IF($M27="Inativo","Não",IF($N27="","Sim",IF(TODAY()-$N27>180,"Sim","Não"))))
A28: araujo-jorge | B28: Hospital de Câncer Araújo Jorge (ACCG) | C28: Saúde | D28: Goiânia | J28: https://www.accg.org.br | K28: Único Centro de Alta Complexidade em Oncologia (Cacon) do Estado, filantrópico com atendimento SUS. Acesso pela regulação. Houve suspensões de novos atendimentos em 2025: confirme antes. | L28: Protótipo do app (ver aba Fontes) | M28: A conferir | P28: =IF($A28="","",IF($M28="Inativo","Não",IF($N28="","Sim",IF(TODAY()-$N28>180,"Sim","Não"))))
A29: capsi | B29: CAPSi estadual, saúde mental de crianças e adolescentes | C29: Saúde | D29: Goiânia | F29: Rua 72 c/ Av. H, s/n, Parque da Criança, Jardim Goiás, Goiânia, CEP 74805-480 | G29: (62) 3201-4346 / (62) 3201-4473 | H29: capsiestadual@gmail.com | K29: De 3 a 17 anos, com os pais ou responsáveis: psicologia, fonoaudiologia, terapia ocupacional, grupos e serviço social. Fonte: SES/GO; confirme o horário por telefone. | L29: SES/GO; confirme o horário por telefone | M29: A conferir | P29: =IF($A29="","",IF($M29="Inativo","Não",IF($N29="","Sim",IF(TODAY()-$N29>180,"Sim","Não"))))
A30: hgg-tx | B30: Ambulatório TX do HGG, saúde da pessoa trans | C30: Saúde | D30: Goiânia | J30: https://goias.gov.br/saude/ambulatorio-para-transexuais-comeca-a-funcionar-no-hgg/ | K30: Hormonização, psicologia, fonoaudiologia e cirurgias pelo SUS. Entrada com encaminhamento da UBS. Fonte: SES/GO. | L30: SES/GO | M30: Ativo | P30: =IF($A30="","",IF($M30="Inativo","Não",IF($N30="","Sim",IF(TODAY()-$N30>180,"Sim","Não"))))
A31: transviver | B31: Ambulatório Transviver (Prefeitura de Goiânia) | C31: Saúde | D31: Goiânia | F31: Nas instalações da UPA Novo Mundo, Goiânia | I31: Seg a sex, 7h às 19h | K31: Para maiores de 18 anos: endocrinologia, psicologia, enfermagem, serviço social e hormônios. Fonte: imprensa, 2024: confirme. | L31: imprensa, 2024: confirme | M31: A conferir | P31: =IF($A31="","",IF($M31="Inativo","Não",IF($N31="","Sim",IF(TODAY()-$N31>180,"Sim","Não"))))
A32: escritorio-social | B32: Escritório Social, apoio a egressos do sistema prisional | C32: Justiça e direitos | D32: Goiânia | F32: Rua 83, nº 484, Setor Sul, Goiânia | K32: Egressos, pré-egressos e liberados condicionais e suas famílias: documentos, trabalho, estudo e políticas sociais. Atendimento voluntário. Inaugurado em dez/2024 (Goiás Social): confirme o horário. | L32: Protótipo do app (ver aba Fontes) | M32: A conferir | P32: =IF($A32="","",IF($M32="Inativo","Não",IF($N32="","Sim",IF(TODAY()-$N32>180,"Sim","Não"))))
A33: pastoral-migrantes | B33: Pastoral dos Migrantes de Goiânia | C33: Rede comunitária e gratuita | D33: Goiânia | G33: (62) 4018-1606 / (62) 99635-1212 | K33: Acolhe migrantes e refugiados (venezuelanos, haitianos e outros): orientação, documentos, trabalho. Tem ponto de atendimento na rodoviária. Fonte: CSEM, publicação antiga: confirme. | L33: CSEM, publicação antiga: confirme | M33: A conferir | P33: =IF($A33="","",IF($M33="Inativo","Não",IF($N33="","Sim",IF(TODAY()-$N33>180,"Sim","Não"))))
A34: cejusc | B34: Cejusc, conciliação gratuita do TJGO | C34: Justiça e direitos | D34: Goiânia | F34: Fórum Cível de Goiânia, Av. Olinda c/ Rua PL-03, Park Lozandes | G34: WhatsApp (62) 99218-2532 | K34: Acordo sobre pensão, guarda, visitas, divórcio e dívidas, sem processo. WhatsApp divulgado nas Semanas da Conciliação de 2023 e 2024: confirme. | L34: Protótipo do app (ver aba Fontes) | M34: A conferir | P34: =IF($A34="","",IF($M34="Inativo","Não",IF($N34="","Sim",IF(TODAY()-$N34>180,"Sim","Não"))))
A35: restbem | B35: Restaurante do Bem (OVG), refeição a R$ 2 | C35: Rede comunitária e gratuita | D35: Goiânia | F35: Av. Araguaia esq. c/ Rua 3, nº 514, Setor Central, Goiânia | J35: https://ovg.org.br | K35: Almoço a R$ 2 para pessoas em vulnerabilidade, idosos e população de rua. Há outras unidades em Goiânia (Campinas) e no interior. Fonte: regulamento OVG, 2024: confirme o horário. | L35: regulamento OVG, 2024: confirme o horário | M35: A conferir | P35: =IF($A35="","",IF($M35="Inativo","Não",IF($N35="","Sim",IF(TODAY()-$N35>180,"Sim","Não"))))
A36: bancoalimentos | B36: Banco de Alimentos da OVG (para entidades) | C36: Rede comunitária e gratuita | D36: Estado | J36: https://ovg.org.br | K36: Entidades sem fins lucrativos que servem refeições se cadastram pelo site da OVG e recebem alimentos da Ceasa. Útil para igrejas e ONGs da rede. | L36: Protótipo do app (ver aba Fontes) | M36: Ativo | P36: =IF($A36="","",IF($M36="Inativo","Não",IF($N36="","Sim",IF(TODAY()-$N36>180,"Sim","Não"))))
A37: pestalozzi | B37: Associação Pestalozzi de Goiânia | C37: Rede comunitária e gratuita | D37: Goiânia | F37: Centro Peter Pan: Praça da Bíblia, Qd. K, Vila Santa Isabel, Goiânia | K37: Atendimento especializado e educação para pessoas com deficiência intelectual ou múltipla. Fonte: convênio com a Seduc/GO: confirme. | L37: convênio com a Seduc/GO: confirme | M37: A conferir | P37: =IF($A37="","",IF($M37="Inativo","Não",IF($N37="","Sim",IF(TODAY()-$N37>180,"Sim","Não"))))
A38: apae-gyn | B38: APAE de Goiânia | C38: Rede comunitária e gratuita | D38: Goiânia | F38: Rua 255, nº 628, Setor Coimbra, Goiânia | K38: Pessoas com deficiência intelectual ou múltipla: pediatria, psicologia, neurologia, fisioterapia, odontologia. Fonte: diretório não oficial: confirme. | L38: diretório não oficial: confirme | M38: A conferir | P38: =IF($A38="","",IF($M38="Inativo","Não",IF($N38="","Sim",IF(TODAY()-$N38>180,"Sim","Não"))))
A39: anhanguera-psi | B39: Clínica-escola de Psicologia da Faculdade Anhanguera de Goiânia | C39: Rede comunitária e gratuita | D39: Goiânia | K39: Psicoterapia, orientação e avaliação psicológica para crianças, adolescentes, adultos e idosos, por alunos supervisionados. Fonte: imprensa, 2025: confirme como agendar. | L39: imprensa, 2025: confirme como agendar | M39: A conferir | P39: =IF($A39="","",IF($M39="Inativo","Não",IF($N39="","Sim",IF(TODAY()-$N39>180,"Sim","Não"))))
A40: mec | B40: MEC: Prouni, Fies e Sisu | C40: Educação | D40: Nacional | G40: Fale Conosco 0800 616161 | J40: https://acessounico.mec.gov.br | K40: Inscrições com a conta gov.br, nas datas de cada edital. Prouni e Fies abrem duas vezes por ano; o Sisu, no início do ano. | L40: Protótipo do app (ver aba Fontes) | M40: Ativo | P40: =IF($A40="","",IF($M40="Inativo","Não",IF($N40="","Sim",IF(TODAY()-$N40>180,"Sim","Não"))))
...

Sheet Políticas
A1: ID (não altere) | B1: Nome | C1: Nome curto | D1: Esfera | E1: Valor ou benefício | F1: Passo a passo (um passo por linha) | G1: Documentos (um por linha) | H1: Onde ir (tipo de lugar) | I1: Outros contatos (IDs da aba Serviços) | J1: Fonte | K1: Conferido em | L1: Mudança de critério pedida
A2: cad | B2: Cadastro Único (CadÚnico) | C2: CadÚnico | D2: Nacional | E2: Porta de entrada | F2: Procurar o CRAS de referência com documento com foto e CPF de todos da casa e comprovante de endereço. Responder à entrevista com o entrevistador do CadÚnico. Guardar o número do NIS e atualizar sempre que mudar endereço, renda ou composição da família (no máximo a cada 2 anos). | G2: CPF de todos da casa (ou título de eleitor) Documento com foto do responsável familiar Comprovante de endereço (ajuda, não é obrigatório) Carteira de trabalho, se tiver | H2: cras | I2: 121 | J2: Ver aba Fontes e docs/levantamento-2026-10-08.md
A3: pbf | B3: Bolsa Família | D3: Nacional | E3: mín. R$ 600/família + adicionais | F3: Fazer ou atualizar o CadÚnico no CRAS. A seleção é automática pelo governo federal, conforme orçamento e ordem de renda. Acompanhar pelo app Bolsa Família, Caixa Tem ou pelo 121. Manter as condicionalidades: vacinação, pré-natal e frequência escolar. | G3: Os mesmos do CadÚnico | H3: cras | I3: 121 | J3: Ver aba Fontes e docs/levantamento-2026-10-08.md
A4: bpc | B4: BPC, Benefício de Prestação Continuada | C4: BPC | D4: Nacional | E4: 1 salário mínimo/mês | F4: Ter o CadÚnico atualizado (obrigatório). Pedir pelo Meu INSS ou pelo 135. Pessoa com deficiência: fazer avaliação social e perícia médica no INSS. Se negado, procurar a Defensoria Pública para recorrer. | G4: Documento com foto e CPF do requerente e da família Laudos e exames (pessoa com deficiência) Número do NIS | H4: cras | I4: 135, dpe, mpf, puc-npj | J4: Ver aba Fontes e docs/levantamento-2026-10-08.md
A5: tse | B5: Tarifa Social de Energia Elétrica | C5: Tarifa Social | D5: Nacional | E5: Luz grátis até 80 kWh/mês | F5: Ter o CadÚnico atualizado, com o endereço da conta de luz. Desde julho de 2025, o consumo até 80 kWh por mês é gratuito; o que passar disso é cobrado normalmente. Impostos e iluminação pública continuam na conta. A concessão costuma ser automática. Se não aparecer, pedir à distribuidora (Equatorial Goiás) informando o NIS. A conta precisa estar no nome de alguém da família. | G5: NIS Conta de luz no nome de alguém da família | H5: cras | J5: Ver aba Fontes e docs/levantamento-2026-10-08.md
A6: gas | B6: Gás do Povo (botijão gratuito) | C6: Gás do Povo | D6: Nacional | E6: Botijão de 13 kg sem custo | F6: Não há inscrição: o MDS seleciona pelo CadÚnico (atualizado nos últimos 24 meses), com prioridade para quem recebe Bolsa Família. Consultar pelo app Meu Social ou pelo 121. Selecionado: levar o botijão vazio a uma revenda credenciada e trocar pelo cheio, sem pagar. O governo não cobra taxa: desconfie de quem pedir dinheiro. | G6: CPF do responsável familiar | H6: cras | I6: 121 | J6: Ver aba Fontes e docs/levantamento-2026-10-08.md
A7: mcmv | B7: Minha Casa, Minha Vida (Faixa 1) | C7: Minha Casa, Minha Vida | D7: Nacional | E7: Moradia subsidiada | F7: Faixa 1 (baixa renda): inscrição pela prefeitura (Goiânia: site e app Prefeitura 24h) ou pela Agehab, quando abrem cadastro. Faixas 2 e 3: direto na Caixa. Ter o CadÚnico atualizado. Acompanhar a abertura de cadastros: a seleção segue os critérios do edital (mulher chefe de família, PcD, idoso, área de risco, violência doméstica). Enquanto espera: Aluguel Social (Agehab), se tiver direito. | G7: Documento com foto e CPF de todos Comprovante de renda CadÚnico | I7: agehab | J7: Ver aba Fontes e docs/levantamento-2026-10-08.md
A8: pdm | B8: Pé-de-Meia | D8: Nacional | E8: Poupança para estudante | F8: Manter matrícula e frequência no ensino médio público. Família com CadÚnico atualizado. Consultar pelo app Jornada do Estudante ou pela escola. | G8: CPF do estudante | H8: cras | J8: Ver aba Fontes e docs/levantamento-2026-10-08.md
A9: cpi | B9: Carteira da Pessoa Idosa | C9: Carteira da Pessoa Idosa | D9: Nacional | E9: Passagem interestadual gratuita ou com desconto | F9: Fazer ou atualizar o CadÚnico. Emitir a carteira no CRAS ou pelo site da Carteira da Pessoa Idosa (MDS). Reservar a vaga na empresa de ônibus com antecedência. | G9: Documento com foto NIS | H9: cras | J9: Ver aba Fontes e docs/levantamento-2026-10-08.md
A10: plfed | B10: Passe Livre interestadual (pessoa com deficiência) | C10: Passe Livre interestadual | D10: Nacional | E10: Viagem interestadual gratuita | F10: Pedir pelo site do Ministério dos Transportes (Passe Livre). Anexar laudo médico e comprovante de renda ou CadÚnico. | G10: Laudo Documento com foto CadÚnico ou comprovante de renda | H10: cras | J10: Ver aba Fontes e docs/levantamento-2026-10-08.md
A11: maes | B11: Mães de Goiás | D11: Estadual | E11: R$ 300/mês | F11: Não tem inscrição. O Estado seleciona 1 ou 2 vezes por ano pela base do CadÚnico. Manter o CadÚnico atualizado no CRAS, com vacinação e frequência escolar das crianças em dia. A prefeitura avisa por SMS ou WhatsApp o dia e o local de entrega do cartão. Consultar situação em suas.social.go.gov.br/consulta-maesdegoias. 2ª via só pelo (62) 3270-9610. | G11: Documento com foto e CPF da beneficiária (para retirar o cartão) | H11: cras | I11: mxc | J11: Ver aba Fontes e docs/levantamento-2026-10-08.md
A12: inclusivo | B12: Goiás + Inclusivo | D12: Estadual | E12: R$ 500/mês | F12: Seleção automática pelo CadÚnico, sem inscrição. Conferir no CRAS se a deficiência está registrada no cadastro. O município avisa a data de entrega do cartão. | G12: Documento da pessoa com deficiência e do responsável | H12: cras | I12: mxc | J12: Ver aba Fontes e docs/levantamento-2026-10-08.md
A13: dignidade | B13: Dignidade | D13: Estadual | E13: R$ 300/mês | F13: Sem inscrição: entrada automática pelo CadÚnico. Manter o CadÚnico atualizado no CRAS. Dúvidas e 2ª via: (62) 3270-9610. | G13: Documento com foto | H13: cras | I13: mxc | J13: Ver aba Fontes e docs/levantamento-2026-10-08.md
A14: porelas | B14: Goiás Por Elas | D14: Estadual | E14: R$ 300/mês por até 12 meses | F14: Não há inscrição: a medida protetiva é enviada à Seds pelo TJGO, Defensoria ou Batalhão Maria da Penha. Manter o CadÚnico atualizado. A Seds entra em contato para entrega do cartão. Vale enquanto a medida estiver ativa, até 12 meses. | G14: Cópia da medida protetiva Documento com foto | I14: mulherseds, dpe | J14: Ver aba Fontes e docs/levantamento-2026-10-08.md
A15: aluguel | B15: Pra Ter Onde Morar, Aluguel Social | C15: Aluguel Social | D15: Estadual | E15: R$ 350/mês por 18 meses | F15: Inscrição online em aluguelsocial.agehab.go.gov.br ou no app Aluguel Social (Android). Anexar documentos; análise por ordem de inscrição. Indeferida? Corrigir ou recorrer pelo próprio app. O CRAS pode ajudar a fazer a inscrição. | G15: Comprovantes de água e energia Comprovante de 3 anos no município Contrato ou recibo de aluguel CadÚnico ativo | H15: cras | I15: agehab | J15: Ver aba Fontes e docs/levantamento-2026-10-08.md
A16: ple | B16: Passe Livre Estudantil | D16: Estadual | E16: 48 viagens/mês | F16: Cadastro em juventude.go.gov.br com documentos e foto. Aprovado, agendar a retirada no Vapt Vupt em vaptvupt.go.gov.br/agendamento. Recadastro a cada período letivo. Bloqueio: justificar pelo site da SitPass. | G16: RG CPF Comprovante de endereço Comprovante de matrícula Foto 3x4 | I16: juventude | J16: Ver aba Fontes e docs/levantamento-2026-10-08.md
A17: aprendiz | B17: Aprendiz do Futuro | D17: Estadual | E17: Socioaprendizagem remunerada | F17: Acompanhar a abertura de inscrições em aprendizdofuturo.org.br. Ter CadÚnico (exigido na contratação). Vagas reservadas para PcD. | G17: Documentos do jovem e do responsável Declaração escolar | I17: aprendiz | J17: Ver aba Fontes e docs/levantamento-2026-10-08.md
A18: ciptea | B18: CIPTEA, Carteira de Identificação da Pessoa com Autismo | C18: CIPTEA | D18: Estadual | E18: Documento, válido 5 anos | F18: Preencher o requerimento (site da Seds). Levar à Unidade Maria Xavier Caiado, seg a sex, 8h às 18h. No interior, pedir pelo e-mail pcd@goias.gov.br. Retirar em até 60 dias. | G18: Relatório de neurologista, psiquiatra ou pediatra Certidão de nascimento ou RG com CPF Documentos do responsável Comprovante de endereço em Goiás Foto (ou tirar na hora) | I18: pcd | J18: Ver aba Fontes e docs/levantamento-2026-10-08.md
A19: plpcd | B19: Passe Livre intermunicipal da pessoa com deficiência | C19: Passe Livre PcD | D19: Estadual | E19: Ônibus entre cidades de Goiás | F19: Levar documentos à Unidade Maria Xavier Caiado (Goiânia) ou pedir pelo WhatsApp (62) 98104-3652. Retirar em até 60 dias. Validade de 3 anos. | G19: Laudo de especialista (validade 1 ano) Espelho do CadÚnico Comprovante de residência em Goiás Documentos do acompanhante, se o laudo indicar | I19: pcd | J19: Ver aba Fontes e docs/levantamento-2026-10-08.md
A20: passaporte | B20: Passaporte da Pessoa Idosa | C20: Passaporte da Pessoa Idosa | D20: Estadual | E20: Até 4 viagens/mês entre cidades de Goiás | F20: Goiânia: Unidade Maria Xavier Caiado. Outros municípios: CRAS ou Secretaria de Assistência Social. Comprar o bilhete com até 5h de antecedência (até 500 km). | G20: RG e CPF Comprovante do CadÚnico | H20: cras | I20: passaporte | J20: Ver aba Fontes e docs/levantamento-2026-10-08.md
A21: credito | B21: Crédito Social | D21: Estadual | E21: Até R$ 5 mil, parcela única | F21: Ter CadÚnico de baixa renda. Fazer o curso de capacitação indicado (Seds/Sebrae, Retomada ou Seapa). Receber cartão para compra de equipamentos no comércio local. | G21: CadÚnico Documento com foto | H21: cras | J21: Ver aba Fontes e docs/levantamento-2026-10-08.md
A22: registro | B22: 2ª via gratuita de certidão (Registro Civil) | C22: 2ª via de certidão | D22: Estadual | E22: Gratuito | F22: Ir à Seds (Bloco B, sala 2) ou a um evento do Goiás Social. Sem nenhum dado do registro, a Seds encaminha à Defensoria. | G22: Cópia de qualquer documento, se tiver Comprovante de endereço Telefone | I22: registro, dpe | J22: Ver aba Fontes e docs/levantamento-2026-10-08.md
A23: enem | B23: Enem e isenção da taxa | C23: Enem | D23: Nacional | E23: Porta de entrada para Prouni, Fies e Sisu | F23: Pedir a isenção da taxa na Página do Participante, com a conta gov.br, no prazo do Inep (em abril). Fazer a inscrição no Enem no período do edital, mesmo quem já tem a isenção. Fazer as duas provas. Para Prouni e Fies, a média precisa ser de pelo menos 450 pontos, sem zerar a redação. Quem tinha isenção e faltou precisa justificar a falta para ter isenção no ano seguinte. | G23: CPF Conta gov.br NIS, se estiver no CadÚnico | I23: inep | J23: Ver aba Fontes e docs/levantamento-2026-10-08.md
A24: prouni | B24: Prouni, bolsa em faculdade particular | C24: Prouni | D24: Nacional | E24: Bolsa de 100% ou 50% | F24: Fazer o Enem e conseguir média de pelo menos 450 pontos, sem zerar a redação. Inscrever-se no Prouni com a conta gov.br, nas datas do edital (duas vezes por ano), escolhendo até duas opções de curso. Acompanhar as chamadas e a lista de espera. Pré-selecionado: levar os documentos à faculdade no prazo, para comprovar renda e escola. Manter frequência e aprovação para não perder a bolsa. | G24: Documento com foto e CPF Comprovantes de renda de todos da casa Histórico do ensino médio Comprovante de endereço | I24: mec | J24: Ver aba Fontes e docs/levantamento-2026-10-08.md
A25: fies | B25: Fies e Fies Social, financiamento da faculdade | C25: Fies | D25: Nacional | E25: Financia até 100% no Fies Social | F25: Fazer o Enem (de 2010 em diante) com média de pelo menos 450 pontos, sem zerar a redação. Prova feita como treineiro não vale. Inscrever-se no Fies com a conta gov.br, nas datas do edital (duas vezes por ano). Fies Social: a vaga é identificada pelo CPF na base do CadÚnico. Atualize o cadastro antes da inscrição. Pré-selecionado: validar a inscrição na comissão da faculdade (CPSA) e assinar o contrato no banco. As parcelas do financiamento são pagas depois de formado. | G25: Documento com foto e CPF Comprovantes de renda de todos da casa Conta gov.br | I25: mec | J25: Ver aba Fontes e docs/levantamento-2026-10-08.md
A26: cotas | B26: Universidade pública: Sisu e cotas | C26: Sisu e cotas | D26: Nacional | E26: Gratuito | F26: Fazer o Enem. Inscrever-se no Sisu com a conta gov.br, no início do ano, escolhendo a modalidade de cota. UEG: acompanhar o edital do processo seletivo próprio. Aprovado por cota: levar na matrícula os comprovantes de escola pública e de renda. Já na universidade, procurar a assistência estudantil. | G26: Histórico escolar do ensino médio Comprovantes de renda de todos da casa (cota de renda) Documento com foto e CPF | I26: mec | J26: Ver aba Fontes e docs/levantamento-2026-10-08.md
A27: probem | B27: ProBem, bolsa universitária do Estado (OVG) | C27: ProBem | D27: Estadual | E27: Bolsa integral ou parcial | F27: Ter o CadÚnico feito ou atualizado em Goiás antes da data de corte do edital. Acompanhar a abertura das inscrições no site da OVG (uma vez por semestre). Inscrever-se pelo site da OVG, matriculada ou aprovada em curso presencial de faculdade parceira (confira o edital). Acompanhar o resultado e manter frequência e aprovação. | G27: Documento com foto e CPF Comprovante de matrícula NIS | I27: ovg | J27: Ver aba Fontes e docs/levantamento-2026-10-08.md
A28: pnaes | B28: Assistência estudantil na faculdade | C28: Assistência estudantil | D28: Nacional | E28: Alimentação, moradia, transporte | F28: Procurar a pró-reitoria ou o setor de assistência estudantil da instituição. Acompanhar os editais de auxílio: alimentação, moradia, transporte, creche. Levar os comprovantes de renda da família. Estudante indígena ou quilombola em universidade federal: perguntar pela Bolsa Permanência do MEC. | G28: Comprovantes de renda de todos da casa Comprovante de matrícula Documento com foto e CPF | J28: Ver aba Fontes e docs/levantamento-2026-10-08.md
A29: eja | B29: Terminar os estudos: EJA e Encceja | C29: EJA e Encceja | D29: Nacional | E29: Gratuito | F29: Encceja: inscrição no site do Inep com a conta gov.br, no período do edital. A prova é gratuita. Aprovado em todas as áreas: pedir o certificado à Secretaria de Educação indicada na inscrição. Prefere estudar em sala: matrícula na EJA da escola estadual ou municipal mais próxima. Com o certificado do ensino médio, já pode fazer o Enem e tentar Prouni, Fies e Sisu. | G29: Documento com foto e CPF Histórico escolar, se tiver Comprovante de endereço (para a EJA) | I29: inep | J29: Ver aba Fontes e docs/levantamento-2026-10-08.md
A30: ceaf | B30: Medicamento de alto custo (Componente Especializado, Cemac Juarez Barbosa) | C30: Alto custo | D30: Estadual | E30: Gratuito pelo SUS | F30: Confirmar se o medicamento é fornecido para a doença (CID): consultar a "Relação de medicamentos, doenças e agravos" no site da Cemac. Na consulta, pedir ao médico (SUS ou particular) a LME (Laudo de Solicitação, Avaliação e Autorização de Medicamentos) preenchida, a receita e os exames exigidos pelo protocolo da doença. Baixar no site da Cemac a lista de documentos e exames da doença e conferir se está tudo junto. Criar ou acessar a conta gov.br do paciente. Abrir o pedido online no go.gov.br: serviço "Solicitar abertura de processo ou alteração e/ou inclusão de medicamentos de alto custo". Acompanhar em "Minhas solicitações". A análise leva até 5 dias úteis. Se faltar documento, o pedido volta com a pendência para corrigir. Aprovado: retirar presencialmente. Quem mora em Goiânia retira na Cemac. No interior e na região metropolitana, o local (município ou policlínica) é informado no processo. Renovar online antes de vencer o período autorizado, com nova LME e receita (análise em até 10 dias úteis). Mudou só a dose? Levar a nova receita e o protocolo direto ao guichê de dispensação. Pedido negado ou remédio fora da lista: guardar a resposta por escrito e procurar a Defensoria Pública, que avalia pedido administrativo ou ação judicial. | G30: LME preenchida e assinada pelo médico Receita médica Exames e laudos exigidos pelo protocolo da doença Documento com foto e CPF do paciente Cartão Nacional de Saúde (CNS) Comprovante de endereço Conta gov.br do paciente | I30: cemac, dpe, puc-npj, mpgo, 136 | J30: Ver aba Fontes e docs/levantamento-2026-10-08.md
A31: fpop | B31: Farmácia Popular | D31: Nacional | E31: Gratuito, sem limite de renda | F31: Conferir se o tratamento está entre as indicações do programa (quadro abaixo). Ter receita válida com nome do paciente, nome do medicamento, dose e posologia. Vale receita do SUS ou de médico particular. Ir a uma farmácia com o selo "Aqui Tem Farmácia Popular" (ou consultar o painel de farmácias credenciadas no gov.br). Ligar antes para confirmar se tem o item. Apresentar documento oficial com foto e CPF. O medicamento é entregue de graça. Não pode ir? Um representante legal ou procurador retira com a receita, documentos com foto e CPF dos dois e a procuração ou decisão judicial. Remédio em falta ou recusa indevida: registrar no Disque Saúde 136. Os mesmos medicamentos também saem na UBS do bairro. | G31: Documento oficial com foto e CPF Receita médica dentro da validade Fralda geriátrica: prescrição, laudo ou atestado (PcD: com o CID) Absorvente: autorização do Dignidade Menstrual, válida por 180 dias | I31: fp, 136 | J31: Ver aba Fontes e docs/levantamento-2026-10-08.md
A32: pep | B32: PEP, Profilaxia Pós-Exposição ao HIV | C32: PEP | D32: Rede de proteção | E32: Urgente: até 72h | F32: Ir imediatamente a uma UPA ou CAIS 24h, ou ao HDT. Não esperar o dia seguinte. Fazer o teste rápido de HIV no próprio serviço. Receber os antirretrovirais para 28 dias e tomar todos os dias, sem parar. Retornar para os testes de acompanhamento no CTA Cidade Jardim ou na UBS. Violência sexual: além da PEP, procurar o Hospital Estadual da Mulher (mulheres) e registrar ocorrência, se quiser. | G32: Documento, se tiver. A falta de documento não impede o atendimento. | H32: pep | J32: Ver aba Fontes e docs/levantamento-2026-10-08.md
A33: hivcare | B33: Cuidado contínuo para pessoa vivendo com HIV | C33: Cuidado em HIV | D33: Rede de proteção | E33: SUS gratuito e sigiloso | F33: Fazer o teste rápido na UBS ou no CTA Cidade Jardim. Resultado reagente: o próprio serviço faz a confirmação e o aconselhamento. Vincular-se ao SAE (Serviço de Atendimento Especializado) do CTA Cidade Jardim ou ao HDT para consulta com infectologista. Fazer os exames iniciais (carga viral, CD4 e outros) e começar o tratamento o quanto antes. O tratamento não espera o resultado do CD4. Retirar os antirretrovirais todo mês na unidade dispensadora (o CTA Cidade Jardim faz a entrega contínua). Levar o cartão do SUS. Repetir carga viral e consultas conforme a agenda do SAE. A meta é carga viral indetectável. Gestante vivendo com HIV: pré-natal com acompanhamento do SAE e do programa Prevenir para a Vida do HDT, para evitar a transmissão ao bebê. Apoio emocional: UBS, CAPS ou CVV 188. Discriminação no trabalho, escola ou serviço: Defensoria Pública ou Disque 100. | G33: Cartão do SUS Documento com foto (não é exigido para o teste) | H33: hiv | I33: ceapsol, 100, mpt | J33: Ver aba Fontes e docs/levantamento-2026-10-08.md
A34: prep | B34: PrEP, Profilaxia Pré-Exposição ao HIV | C34: PrEP | D34: Rede de proteção | E34: Comprimido gratuito | F34: Procurar o CTA Cidade Jardim ou o HDT. Fazer teste de HIV e outros exames de triagem. Iniciar o uso diário (ou sob demanda, se indicado pelo profissional). Voltar a cada consulta para testar e retirar novos frascos. | G34: Documento com foto Cartão do SUS | H34: hiv | J34: Ver aba Fontes e docs/levantamento-2026-10-08.md
A35: mp | B35: Ministério Público: quando e como acionar | C35: Ministério Público | D35: Rede de proteção | E35: Gratuito, sem advogado | F35: Primeiro, pedir o serviço por escrito e guardar o comprovante: protocolo, número de atendimento, resposta negativa, receita, laudo ou print. Reclamar na ouvidoria do órgão (SUS 136, ouvidoria da Seds, da prefeitura). Muitas vezes resolve sem processo. Caso individual que precisa de ação na Justiça (um remédio para uma pessoa, guarda, pensão, vaga): Defensoria Pública ou escritório-modelo. Caso que atinge muitas pessoas, ou pessoa vulnerável sem proteção (criança, idoso, PcD, população de rua, falta geral de remédio, fila de cirurgia, escola sem vaga): fazer representação ao Ministério Público certo (quadro abaixo). Registrar a representação no atendimento ao cidadão do site do MP ou presencialmente na promotoria da comarca. Pode pedir sigilo da identidade. Anotar o número da representação e acompanhar. O promotor pode requisitar informações, fazer recomendação, acordo (TAC) ou ação civil pública. Vítima ou testemunha ameaçada: pedir ao promotor do caso a inclusão no Provita. | G35: Relato curto: o que aconteceu, quando, onde, quem foi afetado Comprovantes: protocolos, negativas, laudos, receitas, fotos Contato para retorno (pode pedir sigilo) | I35: mpgo, mpgo-dh, mpf, mpt, dpe | J35: Ver aba Fontes e docs/levantamento-2026-10-08.md
A36: r-mulher | B36: Rede de proteção à mulher | C36: Proteção à mulher | D36: Rede de proteção | E36: Atendimento 24h | F36: Perigo agora: 190 (PM) ou 153 (GCM Goiânia). Registrar ocorrência e pedir medida protetiva na DEAEM (24h). Acompanhamento social, psicológico e jurídico no Centro de Referência Cora Coralina. Risco de morte: Casa Abrigo Sempre Viva, acessada pela rede. Violência sexual: Hospital Estadual da Mulher em até 72h. | G36: Documento com foto, se possível. Não é obrigatório para ser atendida. | H36: mulher | I36: mpgo-gen, cevam, puc-npj | J36: Ver aba Fontes e docs/levantamento-2026-10-08.md
A37: r-crianca | B37: Proteção à criança e ao adolescente | C37: Proteção à criança | D37: Rede de proteção | E37: Conselho Tutelar | F37: Acionar o Conselho Tutelar da região (plantão à noite e no fim de semana). Denúncia anônima: Disque 100. Acompanhamento da família no CREAS. Lesão ou violência sexual: UPA, hospital ou SAMU 192. | G37: Não é preciso documento para denunciar | H37: ct | I37: dpca, mpgo | J37: Ver aba Fontes e docs/levantamento-2026-10-08.md
A38: r-idoso | B38: Proteção a idosos e pessoas com deficiência | C38: Proteção ao idoso e PcD | D38: Rede de proteção | E38: CREAS | F38: Denunciar pelo Disque 100 ou pelo 197 (Polícia Civil). Crime contra a pessoa idosa: Delegacia do Idoso (Goiânia). Acompanhamento no CREAS da região. Casos graves: Ministério Público e Defensoria. | H38: creas | I38: 100, deai, mpgo | J38: Ver aba Fontes e docs/levantamento-2026-10-08.md
A39: r-rua | B39: Atendimento à população em situação de rua | C39: População de rua | D39: Rede de proteção | E39: Centro POP | F39: Ir ao Centro POP (7h às 17h). Fazer o CadÚnico usando o endereço do Centro POP. Pedir vaga em acolhimento pela equipe do Centro POP. Sem documento: 2ª via de certidão e Defensoria. | G39: Nenhum documento é exigido para o primeiro atendimento | H39: pop | I39: mpgo-dh | J39: Ver aba Fontes e docs/levantamento-2026-10-08.md
A40: crise | B40: Manejo da crise suicida | C40: Crise suicida | D40: Rede de proteção | E40: Agir no mesmo dia | F40: Não deixe a pessoa sozinha. Fique com ela, ou com alguém de confiança, até o próximo cuidado começar. Pergunte diretamente: "Você está pensando em se matar?". Perguntar não induz; abre espaço para a pessoa falar. Avalie o risco: há plano (como, quando, onde)? Tem acesso ao meio? Já tentou antes? Está sob efeito de álcool ou drogas agora? Risco alto (plano com meio disponível, tentativa recente, intoxicação, agitação): SAMU 192 ou pronto atendimento agora. A pessoa não vai sozinha. Tomou remédio ou veneno: pronto atendimento mesmo sem sintomas, levando a embalagem. Orientação 24h no CIATox Goiás, 0800 646 4350. Para conversar a qualquer hora: CVV 188, ligação gratuita e sigilosa. Ofereça ligar junto ou salvar o número no celular dela. Reduza o acesso aos meios: com a família, guarde remédios, venenos, armas e cordas fora do alcance. Acione a rede de apoio: um familiar ou pessoa de confiança, de preferência com o conhecimento da pessoa. O risco à vida permite quebrar o sigilo, contando só o necessário. Registre a decisão. Faça com ela um plano de segurança (quadro abaixo). O plano fica com a pessoa, não no app. Garanta o seguimento: CAPS (acesso direto) ou UBS nos próximos dias, com data marcada antes de a pessoa sair. Retome o contato se ela faltar. Tentativa ou autolesão: o serviço de saúde faz a notificação compulsória (ficha de violência autoprovocada, SINAN) em até 24h. A notificação não é denúncia; serve para a rede acompanhar. Cuide de você: discuta o caso com a equipe ou com a supervisão. | G40: Nenhum documento é exigido no atendimento de urgência | H40: saude | I40: 188, ciatox | J40: Ver aba Fontes e docs/levantamento-2026-10-08.md
...

Sheet Temas
A1: Chave (não altere) | B1: Título | C1: Palavras-chave (sem acento, separadas por vírgula) | D1: Liga a situação do app | E1: Passo a passo (um por linha) | F1: Contatos (IDs da aba Serviços) | G1: Frase de urgência
A2: avc | B2: AVC (derrame) | C2: avc, derrame, boca torta, fala enrolada, nao consegue falar, braco fraco, perdeu a forca, paralisia | E2: Acontecendo agora: ligar 192 (SAMU). O tratamento do AVC depende do tempo, cada minuto conta. Sinais de alerta: boca torta ao sorrir, braço fraco ao levantar os dois, fala enrolada ou confusa. Anotar a hora em que os sintomas começaram e os remédios que a pessoa usa. Não dar comida, bebida nem remédio; se vomitar, deitar a pessoa de lado. AVC que já passou: pedir na UBS o encaminhamento para reabilitação (fisioterapia, fonoaudiologia) e acompanhar pressão, diabetes e remédios na UBS. Novo sinal de AVC a qualquer momento: 192 de novo. | F2: samu, hugo | G2: Se os sinais de AVC estão acontecendo agora (boca torta, braço fraco, fala enrolada): ligue 192 (SAMU) e anote a hora em que começaram.
A3: emergencia | B3: Emergência médica | C3: infarto, dor no peito, falta de ar, desmai, convuls, sangramento, acidente, inconsciente, overdose, engasg, queimadura grave | E3: Risco de vida: ligar 192 (SAMU). O médico regulador orienta pelo telefone e envia a ambulância. Sem risco de vida, mas precisa de atendimento hoje: UPA ou CAIS 24h. Intoxicação ou picada de animal: CIATox 0800 646 4350, 24h. | F3: samu, ciatox | G3: Se há risco de vida agora: ligue 192 (SAMU).
A4: reabilitacao | B4: Reabilitação: fisioterapia, fono, órteses e próteses | C4: reabilita, fisioterap, fisio, pos cirurg, pos-cirurg, sequela, protese, ortese, cadeira de rodas, andador, fonoaudio, terapia ocupacional, amputa, lesao medular | E4: Pedir na UBS, ou ao médico que fez a cirurgia, o encaminhamento para reabilitação, com relatório e exames. A UBS coloca o pedido na regulação. A vaga (fisioterapia, fonoaudiologia, CRER ou clínica-escola) é marcada pela Secretaria de Saúde. Em Goiânia, o CRER é a referência estadual em reabilitação. A primeira consulta vem pela regulação, não por procura direta. Cadeira de rodas, órtese e prótese também são pedidas pela UBS, com prescrição. Pessoa que não consegue sair de casa: perguntar na UBS ou no hospital pelo Melhor em Casa (atendimento no domicílio). Demora longa: guardar o protocolo e procurar a Ouvidoria do SUS (136) ou a Defensoria. | F4: crer, puc-vida, reggyn, 136
A5: acamado | B5: Pessoa acamada ou que depende de cuidados | C5: acamad, cuidador, home care, melhor em casa, curativo em casa, sonda, oxigenio, nao anda, dependente de cuidado | E5: Pedir à UBS a visita da equipe de saúde da família. Atendimento em casa pelo SUS (Melhor em Casa): pedido pela UBS ou pelo hospital, na alta. Fralda geriátrica de graça na Farmácia Popular (60 anos ou mais, ou pessoa com deficiência), com receita. Renda baixa: BPC, se a família tiver até 1/4 do salário mínimo por pessoa. O CRAS orienta. Cuidador sobrecarregado: o CRAS orienta sobre apoio à família. | F5: fp, 121
A6: fila | B6: Consulta, exame ou cirurgia demorando | C6: fila, demora, esperando, aguardando, especialista, ressonancia, tomografia, regulacao, marcar consulta | E6: Confirmar na UBS se o pedido está na regulação e anotar o número do protocolo. Demora sem resposta: Ouvidoria do SUS, 136. Risco à saúde pela demora: Defensoria Pública ou Ministério Público, com laudo e protocolo. | F6: reggyn, 136, dpe, mpgo
A7: familia | B7: Pensão alimentícia, guarda, divórcio, paternidade | C7: pensao aliment, pensao do filho, pensao para, guarda, divorcio, separacao, paternidade, dna, visita dos filhos, uniao estavel, inventario, heranca, curatela, interdicao | E7: Defensoria Pública: atende de graça quem não pode pagar advogado. Acordo sem processo: Cejusc do TJGO (conciliação gratuita sobre pensão, guarda, visitas e divórcio). Levar documentos pessoais, certidões (nascimento dos filhos, casamento) e comprovantes de renda e despesas. Alternativa: escritório-modelo de faculdade de Direito (NPJ PUC Goiás). Se houver violência: medida protetiva na DEAEM ou na Defensoria. | F7: dpe, cejusc, puc-npj
A8: inss | B8: INSS: aposentadoria, auxílio-doença, pensão por morte | C8: inss, aposentad, auxilio doenca, auxilio-doenca, incapacidade, pericia, pensao por morte, auxilio reclusao, salario maternidade | E8: Pedir pelo Meu INSS (app ou site, com a conta gov.br) ou pelo telefone 135. Auxílio por incapacidade: levar laudo e exames à perícia. Negado: recorrer pelo Meu INSS em até 30 dias, ou procurar a Defensoria Pública da União ou o NPJ. BPC (LOAS): veja o assunto Renda e benefícios. | F8: 135, puc-npj
A9: emprego | B9: Desemprego e seguro-desemprego | C9: desempreg, seguro desemprego, seguro-desemprego, emprego, curriculo, demitid, fgts | E9: Seguro-desemprego: pedir pelo app Carteira de Trabalho Digital ou pelo gov.br, do 7º ao 120º dia depois da demissão. Vagas e orientação: Sine Goiânia, com agendamento pelo app Prefeitura 24h. Quer abrir um negócio: veja o assunto Trabalho (Crédito Social). Família sem renda: CRAS, para CadÚnico e benefícios. | F9: sine
A10: dividas | B10: Dívidas, golpes e problemas de consumo | C10: divida, nome sujo, negativad, serasa, juros, emprestimo, consignado, golpe, fraude, cobranca, cartao de credito, superendivid | E10: Procon Goiás: reclamação e renegociação de dívidas (Núcleo de Apoio aos Superendividados). Negociação online: consumidor.gov.br. Golpe ou fraude: registrar boletim de ocorrência e avisar o banco na hora. Desconto indevido na aposentadoria: Meu INSS e Defensoria. | F10: procon, dpe
A11: desastre | B11: Enchente, incêndio ou desabamento | C11: enchente, alagamento, incendio, desabamento, desabrigad, deslizamento, perdeu a casa | E11: Risco agora: Bombeiros 193 ou Defesa Civil 199. Perdeu bens ou a casa: CRAS, para benefício eventual e acolhimento provisório. Documentos perdidos: 2ª via gratuita de certidão (assunto Documentos). | F11: 121 | G11: Risco agora: 193 (Bombeiros) ou 199 (Defesa Civil).
A12: funeral | B12: Morte na família: funeral e luto | C12: funeral, enterro, sepultamento, obito, faleceu, falecimento, luto, morreu | E12: Família de baixa renda: pedir o auxílio funeral (benefício eventual) no CRAS ou na Secretaria de Assistência Social. Certidão de óbito: no cartório, com a declaração de óbito do hospital ou do IML. Pensão por morte: Meu INSS ou 135. Luto difícil: UBS, CAPS ou CVV 188. Se a morte foi por suicídio, ofereça acompanhamento à família. | F12: 121, 188
A13: rg | B13: RG, CPF ou carteira de trabalho | C13: rg, identidade, cpf, carteira de trabalho, titulo de eleitor, documento perdido, documentos perdidos | E13: Carteira de Identidade: agendar no Vapt Vupt (vaptvupt.go.gov.br), levando a certidão de nascimento ou casamento. CPF: de graça pelo site da Receita Federal. Carteira de Trabalho: é digital, pelo app Carteira de Trabalho Digital com a conta gov.br. Sem certidão: 2ª via gratuita (assunto Documentos).
A14: apostas | B14: Apostas e bets | C14: bet, bets, aposta, apostas, apostando, apostador, cassino, tigrinho, jogo do tigre, jogo do bicho, jogos de azar, roleta, aviator | D14: apostas
A15: games | B15: Jogos eletrônicos e internet | C15: videogame, video game, jogos eletronicos, jogo eletronico, games, free fire, roblox, minecraft, fortnite, viciado em jogo, vicio em jogo, viciado no celular, vicio em celular, vicio em internet | D15: games
A16: drogas | B16: Álcool e outras drogas | C16: alcool, bebida, bebe muito, alcoolismo, alcoolatra, droga, drogas, crack, cocaina, maconha, dependencia quimica, dependente quimico, internar, internacao, clinica de recuperacao, comunidade terapeutica | D16: drogas
A17: violsexual | B17: Violência sexual | C17: estupro, estuprad, abuso sexual, abusada, abusado, violencia sexual, assedio sexual, importunacao | E17: Nas primeiras 72h: atendimento de saúde imediato para profilaxia de HIV e IST e contracepção de emergência. Em Goiânia, o Hemu tem ambulatório próprio para vítimas de violência sexual (procura direta ou encaminhamento); também UPA ou CAIS 24h. Registrar ocorrência é um direito, não uma condição para o atendimento de saúde. Mulher: DEAEM (24h). Criança ou adolescente: DPCA e Conselho Tutelar. Gravidez resultante de estupro: a interrupção é prevista em lei. O Hemu é a referência estadual. Acompanhamento psicológico e social: CREAS e, para mulheres, Centro de Referência Cora Coralina. Criança ou adolescente: comunicar sempre ao Conselho Tutelar. | F17: hem, deaem, dpca, cora, 100 | G17: Violência sexual nas últimas 72h: atendimento de saúde agora (profilaxia de HIV e IST e contracepção de emergência), mesmo sem registrar ocorrência.
A18: violidoso | B18: Violência, abandono ou exploração de pessoa idosa ou com deficiência | C18: violencia contra idoso, violencia contra idosa, violencia contra o idoso, violencia contra a idosa, violencia contra pessoa idosa, violencia contra a pessoa idosa, violencia contra pessoa com deficiencia, violencia contra a pessoa com deficiencia, idoso apanha, idosa apanha, avo apanha, avo esta apanhando, avo ta apanhando, bate no idoso, bate na idosa, bate no avo, bate na avo, bateu no avo, bateu na avo, batendo no avo, batendo na avo, agride o idoso, agride a idosa, agrediu o idoso, agrediu a idosa, agressao ao idoso, agressao a idosa, maus tratos ao idoso, maus tratos a idosa, maus tratos contra idoso, maus tratos contra a pessoa idosa, maus tratos a pessoa com deficiencia, idoso sofrendo maus, idosa sofrendo maus, idoso sofrendo violencia, idosa sofrendo violencia, idoso maltratad, idosa maltratad, maltrata o idoso, maltrata a idosa, maltrata o avo, maltrata a avo, idoso abandonad, idosa abandonad, abandono de idoso, abandono do idoso, abandono da idosa, idoso largad, idosa largad, idoso negligenciad, idosa negligenciad, negligencia com idoso, negligencia com o idoso, negligencia com a idosa, idoso trancad, idosa trancad, pega o cartao do aposentad, pegam o cartao do aposentad, toma o cartao do aposentad, fica com o cartao do aposentad, pega a aposentadoria, pegam a aposentadoria, toma a aposentadoria, fica com a aposentadoria, fica com o dinheiro da aposentadoria, fica com o dinheiro do idoso, exploracao financeira, emprestimo no nome do idoso, emprestimo no nome da idosa, emprestimo no nome do avo, emprestimo no nome da avo | D18: violIdoso
A19: discriminacao | B19: Discriminação: racismo, xenofobia, intolerância religiosa, LGBTfobia | C19: racismo, racista, injuria racial, ofensa racial, preconceito, discrimina, xenofob, por ser nordestin, por ser estrangeir, por ser venezuelan, por ser haitian, volta pro seu pais, homofobia, homofob, transfobia, lgbtfobia, intolerancia religiosa, racismo religioso, atacaram o terreiro, ataque ao terreiro, invadiram o terreiro, por ser do candomble, por ser da umbanda, por causa da religiao, por causa da minha religiao, perseguido pela religiao, perseguida pela religiao, por ser evangelic, por ser catolic, por ser espirita, por ser muculman, por ser judeu, por ser judia, macumbeir, chutaram a imagem, capacitismo, capacitista, idadismo, etarismo, xingou de macaco | D19: discrim
A20: trans | B20: Pessoa trans: saúde e documentos | C20: pessoa trans, mulher trans, homem trans, menina trans, menino trans, transexual, travesti, transgenero, hormonizacao, nome social, mudar o nome, redesignacao | E20: Saúde: pedir na UBS o encaminhamento para o Ambulatório TX do HGG (hormonização, psicologia, cirurgias). Maiores de 18 em Goiânia também podem procurar o Transviver. Nome social: pode ser usado no SUS, na escola e no CadÚnico, sem mudar documento. Mudar nome e gênero nos documentos: direto no cartório, sem processo e sem cirurgia, para maiores de 18 anos. Defensoria orienta quem não pode pagar as taxas. Violência ou discriminação: Deacri e Disque 100. | F20: hgg-tx, transviver, deacri, dpe
A21: migrante | B21: Migrantes e refugiados | C21: migrante, imigrante, refugiad, venezuelan, haitian, estrangeir, refugio, sem documento brasileiro | E21: O SUS atende sem exigir documento brasileiro. A criança tem direito à matrícula na escola. CadÚnico e benefícios: pode se cadastrar com a Carteira de Registro Nacional Migratório (CRNM) ou o protocolo de refúgio, no CRAS. Documentos, trabalho e orientação: Pastoral dos Migrantes de Goiânia. Regularização migratória com problema: Defensoria Pública da União. Sofreu xenofobia: é crime (Lei 7.716/1989). Registrar na Deacri ou em qualquer delegacia, ou pelo Disque 100. | F21: pastoral-migrantes, deacri, 100, 121
A22: egresso | B22: Saiu do sistema prisional (egresso) e família | C22: egresso, saiu da prisao, saiu da cadeia, ex-detento, ex detento, presidiario, tornozeleira, liberdade condicional, foi preso, esta preso, presidio | E22: Escritório Social (Goiânia): documentos, trabalho, estudo e acesso a políticas sociais para egressos e famílias. Atendimento voluntário. Família de pessoa presa: auxílio-reclusão no INSS, se a pessoa contribuía (Meu INSS ou 135). CadÚnico e benefícios no CRAS; situação de rua: Centro POP. Dúvidas sobre a pena ou o processo: Defensoria Pública. | F22: escritorio-social, dpe, 135
